[2022-10-28 01:24:31,700] [util.py:209]               [INFO]     |====================================================================================================|
[2022-10-28 01:24:31,700] [util.py:216]               [INFO]     |                                     A&E Collection in TV Shows                                     |
[2022-10-28 01:24:31,701] [util.py:220]               [INFO]     |====================================================================================================|
[2022-10-28 01:24:31,701] [plex_meta_manager.py:750]  [INFO]     |                                                                                                    |
[2022-10-28 01:24:31,701] [util.py:216]               [INFO]     |==================================== Validating A&E Attributes =====================================|
[2022-10-28 01:24:31,702] [builder.py:265]            [DEBUG]    |                                                                                                    |
[2022-10-28 01:24:31,702] [builder.py:266]            [DEBUG]    | Validating Method: template                                                                        |
[2022-10-28 01:24:31,702] [meta.py:83]                [DEBUG]    | Value: ordereddict([('name', 'network'), ('network', '129, 2639, 3688'), ('poster', 'https://theposterdb.com/api/assets/160188')]) |
[2022-10-28 01:24:31,702] [builder.py:330]            [DEBUG]    |                                                                                                    |
[2022-10-28 01:24:31,703] [builder.py:331]            [DEBUG]    | Validating Method: sync_mode                                                                       |
[2022-10-28 01:24:31,703] [builder.py:335]            [DEBUG]    | Value: sync                                                                                        |
[2022-10-28 01:24:31,703] [builder.py:453]            [DEBUG]    |                                                                                                    |
[2022-10-28 01:24:31,703] [builder.py:454]            [DEBUG]    | Validating Method: collection_order                                                                |
[2022-10-28 01:24:31,704] [builder.py:455]            [DEBUG]    | Value: alpha                                                                                       |
[2022-10-28 01:24:31,704] [builder.py:472]            [DEBUG]    |                                                                                                    |
[2022-10-28 01:24:31,704] [builder.py:473]            [DEBUG]    | Validating Method: tmdb_network                                                                    |
[2022-10-28 01:24:31,704] [builder.py:474]            [DEBUG]    | Value: 129, 2639, 3688                                                                             |
[2022-10-28 01:24:32,025] [builder.py:472]            [DEBUG]    |                                                                                                    |
[2022-10-28 01:24:32,026] [builder.py:473]            [DEBUG]    | Validating Method: url_poster                                                                      |
[2022-10-28 01:24:32,026] [builder.py:474]            [DEBUG]    | Value: https://theposterdb.com/api/assets/160188                                                   |
[2022-10-28 01:24:32,026] [builder.py:472]            [DEBUG]    |                                                                                                    |
[2022-10-28 01:24:32,027] [builder.py:473]            [DEBUG]    | Validating Method: sort_title                                                                      |
[2022-10-28 01:24:32,027] [builder.py:474]            [DEBUG]    | Value: +2_A&E                                                                                      |
[2022-10-28 01:24:32,030] [plex.py:685]               [DEBUG]    | Looking for: A&E                                                                                   |
[2022-10-28 01:24:32,030] [builder.py:619]            [INFO]     |                                                                                                    |
[2022-10-28 01:24:32,030] [builder.py:620]            [INFO]     | Validation Successful                                                                              |
[2022-10-28 01:24:32,033] [plex_meta_manager.py:758]  [INFO]     |                                                                                                    |
[2022-10-28 01:24:32,033] [util.py:216]               [INFO]     |====================================== Running A&E Collection ======================================|
[2022-10-28 01:24:32,033] [plex_meta_manager.py:773]  [INFO]     |                                                                                                    |
[2022-10-28 01:24:32,034] [plex_meta_manager.py:774]  [INFO]     | Sync Mode: sync                                                                                    |
[2022-10-28 01:24:32,034] [builder.py:1275]           [DEBUG]    |                                                                                                    |
[2022-10-28 01:24:32,034] [builder.py:1276]           [DEBUG]    | Builder: tmdb_network: 129                                                                         |
[2022-10-28 01:24:32,034] [builder.py:1277]           [INFO]     |                                                                                                    |
[2022-10-28 01:24:32,271] [util.py:162]               [DEBUG]    | Traceback (most recent call last):                                                                 |
[2022-10-28 01:24:32,271] [util.py:162]               [DEBUG]    |   File "C:\Plex-Stack\Plex-Meta-Manager\pmm-venv\lib\site-packages\urllib3\connectionpool.py", line 703, in urlopen |
[2022-10-28 01:24:32,271] [util.py:162]               [DEBUG]    |     httplib_response = self._make_request(                                                         |
[2022-10-28 01:24:32,272] [util.py:162]               [DEBUG]    |   File "C:\Plex-Stack\Plex-Meta-Manager\pmm-venv\lib\site-packages\urllib3\connectionpool.py", line 386, in _make_request |
[2022-10-28 01:24:32,272] [util.py:162]               [DEBUG]    |     self._validate_conn(conn)                                                                      |
[2022-10-28 01:24:32,272] [util.py:162]               [DEBUG]    |   File "C:\Plex-Stack\Plex-Meta-Manager\pmm-venv\lib\site-packages\urllib3\connectionpool.py", line 1040, in _validate_conn |
[2022-10-28 01:24:32,272] [util.py:162]               [DEBUG]    |     conn.connect()                                                                                 |
[2022-10-28 01:24:32,273] [util.py:162]               [DEBUG]    |   File "C:\Plex-Stack\Plex-Meta-Manager\pmm-venv\lib\site-packages\urllib3\connection.py", line 416, in connect |
[2022-10-28 01:24:32,273] [util.py:162]               [DEBUG]    |     self.sock = ssl_wrap_socket(                                                                   |
[2022-10-28 01:24:32,273] [util.py:162]               [DEBUG]    |   File "C:\Plex-Stack\Plex-Meta-Manager\pmm-venv\lib\site-packages\urllib3\util\ssl_.py", line 449, in ssl_wrap_socket |
[2022-10-28 01:24:32,273] [util.py:162]               [DEBUG]    |     ssl_sock = _ssl_wrap_socket_impl(                                                              |
[2022-10-28 01:24:32,274] [util.py:162]               [DEBUG]    |   File "C:\Plex-Stack\Plex-Meta-Manager\pmm-venv\lib\site-packages\urllib3\util\ssl_.py", line 493, in _ssl_wrap_socket_impl |
[2022-10-28 01:24:32,274] [util.py:162]               [DEBUG]    |     return ssl_context.wrap_socket(sock, server_hostname=server_hostname)                          |
[2022-10-28 01:24:32,274] [util.py:162]               [DEBUG]    |   File "C:\Users\Jack\AppData\Local\Programs\Python\Python39\lib\ssl.py", line 500, in wrap_socket |
[2022-10-28 01:24:32,274] [util.py:162]               [DEBUG]    |     return self.sslsocket_class._create(                                                           |
[2022-10-28 01:24:32,274] [util.py:162]               [DEBUG]    |   File "C:\Users\Jack\AppData\Local\Programs\Python\Python39\lib\ssl.py", line 1040, in _create    |
[2022-10-28 01:24:32,275] [util.py:162]               [DEBUG]    |     self.do_handshake()                                                                            |
[2022-10-28 01:24:32,275] [util.py:162]               [DEBUG]    |   File "C:\Users\Jack\AppData\Local\Programs\Python\Python39\lib\ssl.py", line 1309, in do_handshake |
[2022-10-28 01:24:32,275] [util.py:162]               [DEBUG]    |     self._sslobj.do_handshake()                                                                    |
[2022-10-28 01:24:32,275] [util.py:162]               [DEBUG]    | ConnectionResetError: [WinError 10054] An existing connection was forcibly closed by the remote host |
[2022-10-28 01:24:32,276] [util.py:162]               [DEBUG]    |                                                                                                    |
[2022-10-28 01:24:32,276] [util.py:162]               [DEBUG]    | During handling of the above exception, another exception occurred:                                |
[2022-10-28 01:24:32,276] [util.py:162]               [DEBUG]    |                                                                                                    |
[2022-10-28 01:24:32,276] [util.py:162]               [DEBUG]    | Traceback (most recent call last):                                                                 |
[2022-10-28 01:24:32,276] [util.py:162]               [DEBUG]    |   File "C:\Plex-Stack\Plex-Meta-Manager\pmm-venv\lib\site-packages\requests\adapters.py", line 440, in send |
[2022-10-28 01:24:32,277] [util.py:162]               [DEBUG]    |     resp = conn.urlopen(                                                                           |
[2022-10-28 01:24:32,277] [util.py:162]               [DEBUG]    |   File "C:\Plex-Stack\Plex-Meta-Manager\pmm-venv\lib\site-packages\urllib3\connectionpool.py", line 785, in urlopen |
[2022-10-28 01:24:32,277] [util.py:162]               [DEBUG]    |     retries = retries.increment(                                                                   |
[2022-10-28 01:24:32,277] [util.py:162]               [DEBUG]    |   File "C:\Plex-Stack\Plex-Meta-Manager\pmm-venv\lib\site-packages\urllib3\util\retry.py", line 550, in increment |
[2022-10-28 01:24:32,277] [util.py:162]               [DEBUG]    |     raise six.reraise(type(error), error, _stacktrace)                                             |
[2022-10-28 01:24:32,278] [util.py:162]               [DEBUG]    |   File "C:\Plex-Stack\Plex-Meta-Manager\pmm-venv\lib\site-packages\urllib3\packages\six.py", line 769, in reraise |
[2022-10-28 01:24:32,278] [util.py:162]               [DEBUG]    |     raise value.with_traceback(tb)                                                                 |
[2022-10-28 01:24:32,278] [util.py:162]               [DEBUG]    |   File "C:\Plex-Stack\Plex-Meta-Manager\pmm-venv\lib\site-packages\urllib3\connectionpool.py", line 703, in urlopen |
[2022-10-28 01:24:32,278] [util.py:162]               [DEBUG]    |     httplib_response = self._make_request(                                                         |
[2022-10-28 01:24:32,279] [util.py:162]               [DEBUG]    |   File "C:\Plex-Stack\Plex-Meta-Manager\pmm-venv\lib\site-packages\urllib3\connectionpool.py", line 386, in _make_request |
[2022-10-28 01:24:32,279] [util.py:162]               [DEBUG]    |     self._validate_conn(conn)                                                                      |
[2022-10-28 01:24:32,279] [util.py:162]               [DEBUG]    |   File "C:\Plex-Stack\Plex-Meta-Manager\pmm-venv\lib\site-packages\urllib3\connectionpool.py", line 1040, in _validate_conn |
[2022-10-28 01:24:32,279] [util.py:162]               [DEBUG]    |     conn.connect()                                                                                 |
[2022-10-28 01:24:32,279] [util.py:162]               [DEBUG]    |   File "C:\Plex-Stack\Plex-Meta-Manager\pmm-venv\lib\site-packages\urllib3\connection.py", line 416, in connect |
[2022-10-28 01:24:32,280] [util.py:162]               [DEBUG]    |     self.sock = ssl_wrap_socket(                                                                   |
[2022-10-28 01:24:32,280] [util.py:162]               [DEBUG]    |   File "C:\Plex-Stack\Plex-Meta-Manager\pmm-venv\lib\site-packages\urllib3\util\ssl_.py", line 449, in ssl_wrap_socket |
[2022-10-28 01:24:32,280] [util.py:162]               [DEBUG]    |     ssl_sock = _ssl_wrap_socket_impl(                                                              |
[2022-10-28 01:24:32,280] [util.py:162]               [DEBUG]    |   File "C:\Plex-Stack\Plex-Meta-Manager\pmm-venv\lib\site-packages\urllib3\util\ssl_.py", line 493, in _ssl_wrap_socket_impl |
[2022-10-28 01:24:32,281] [util.py:162]               [DEBUG]    |     return ssl_context.wrap_socket(sock, server_hostname=server_hostname)                          |
[2022-10-28 01:24:32,281] [util.py:162]               [DEBUG]    |   File "C:\Users\Jack\AppData\Local\Programs\Python\Python39\lib\ssl.py", line 500, in wrap_socket |
[2022-10-28 01:24:32,281] [util.py:162]               [DEBUG]    |     return self.sslsocket_class._create(                                                           |
[2022-10-28 01:24:32,281] [util.py:162]               [DEBUG]    |   File "C:\Users\Jack\AppData\Local\Programs\Python\Python39\lib\ssl.py", line 1040, in _create    |
[2022-10-28 01:24:32,281] [util.py:162]               [DEBUG]    |     self.do_handshake()                                                                            |
[2022-10-28 01:24:32,282] [util.py:162]               [DEBUG]    |   File "C:\Users\Jack\AppData\Local\Programs\Python\Python39\lib\ssl.py", line 1309, in do_handshake |
[2022-10-28 01:24:32,282] [util.py:162]               [DEBUG]    |     self._sslobj.do_handshake()                                                                    |
[2022-10-28 01:24:32,282] [util.py:162]               [DEBUG]    | urllib3.exceptions.ProtocolError: ('Connection aborted.', ConnectionResetError(10054, 'An existing connection was forcibly closed by the remote host', None, 10054, None)) |
[2022-10-28 01:24:32,282] [util.py:162]               [DEBUG]    |                                                                                                    |
[2022-10-28 01:24:32,282] [util.py:162]               [DEBUG]    | During handling of the above exception, another exception occurred:                                |
[2022-10-28 01:24:32,283] [util.py:162]               [DEBUG]    |                                                                                                    |
[2022-10-28 01:24:32,283] [util.py:162]               [DEBUG]    | Traceback (most recent call last):                                                                 |
[2022-10-28 01:24:32,283] [util.py:162]               [DEBUG]    |   File "C:\Plex-Stack\Plex-Meta-Manager\plex_meta_manager.py", line 783, in run_collection         |
[2022-10-28 01:24:32,283] [util.py:162]               [DEBUG]    |     builder.find_rating_keys()                                                                     |
[2022-10-28 01:24:32,284] [util.py:162]               [DEBUG]    |   File "C:\Plex-Stack\Plex-Meta-Manager\modules\builder.py", line 1279, in find_rating_keys        |
[2022-10-28 01:24:32,284] [util.py:162]               [DEBUG]    |     ids = self.gather_ids(method, value)                                                           |
[2022-10-28 01:24:32,284] [util.py:162]               [DEBUG]    |   File "C:\Plex-Stack\Plex-Meta-Manager\modules\builder.py", line 1267, in gather_ids              |
[2022-10-28 01:24:32,284] [util.py:162]               [DEBUG]    |     return self.config.TMDb.get_tmdb_ids(method, value, self.library.is_movie)                     |
[2022-10-28 01:24:32,284] [util.py:162]               [DEBUG]    |   File "C:\Plex-Stack\Plex-Meta-Manager\modules\tmdb.py", line 278, in get_tmdb_ids                |
[2022-10-28 01:24:32,285] [util.py:162]               [DEBUG]    |     ids, amount = self._discover(attrs, limit, is_movie)                                           |
[2022-10-28 01:24:32,285] [util.py:162]               [DEBUG]    |   File "C:\Plex-Stack\Plex-Meta-Manager\modules\tmdb.py", line 225, in _discover                   |
[2022-10-28 01:24:32,285] [util.py:162]               [DEBUG]    |     tmdb_items = self.Discover.discover_movies(attrs) if is_movie else self.Discover.discover_tv_shows(attrs) |
[2022-10-28 01:24:32,285] [util.py:162]               [DEBUG]    |   File "C:\Plex-Stack\Plex-Meta-Manager\pmm-venv\lib\site-packages\tmdbv3api\objs\discover.py", line 27, in discover_tv_shows |
[2022-10-28 01:24:32,285] [util.py:162]               [DEBUG]    |     return self._get_obj(self._call(self._urls["tv"], urlencode(params)))                          |
[2022-10-28 01:24:32,286] [util.py:162]               [DEBUG]    |   File "C:\Plex-Stack\Plex-Meta-Manager\pmm-venv\lib\site-packages\tmdbv3api\tmdb.py", line 131, in _call |
[2022-10-28 01:24:32,286] [util.py:162]               [DEBUG]    |     req = self.cached_request(method, url, data)                                                   |
[2022-10-28 01:24:32,286] [util.py:162]               [DEBUG]    |   File "C:\Plex-Stack\Plex-Meta-Manager\pmm-venv\lib\site-packages\tmdbv3api\tmdb.py", line 111, in cached_request |
[2022-10-28 01:24:32,286] [util.py:162]               [DEBUG]    |     return requests.request(method, url, data=data)                                                |
[2022-10-28 01:24:32,286] [util.py:162]               [DEBUG]    |   File "C:\Plex-Stack\Plex-Meta-Manager\pmm-venv\lib\site-packages\requests\api.py", line 61, in request |
[2022-10-28 01:24:32,287] [util.py:162]               [DEBUG]    |     return session.request(method=method, url=url, **kwargs)                                       |
[2022-10-28 01:24:32,287] [util.py:162]               [DEBUG]    |   File "C:\Plex-Stack\Plex-Meta-Manager\pmm-venv\lib\site-packages\requests\sessions.py", line 529, in request |
[2022-10-28 01:24:32,287] [util.py:162]               [DEBUG]    |     resp = self.send(prep, **send_kwargs)                                                          |
[2022-10-28 01:24:32,287] [util.py:162]               [DEBUG]    |   File "C:\Plex-Stack\Plex-Meta-Manager\pmm-venv\lib\site-packages\requests\sessions.py", line 645, in send |
[2022-10-28 01:24:32,288] [util.py:162]               [DEBUG]    |     r = adapter.send(request, **kwargs)                                                            |
[2022-10-28 01:24:32,288] [util.py:162]               [DEBUG]    |   File "C:\Plex-Stack\Plex-Meta-Manager\pmm-venv\lib\site-packages\requests\adapters.py", line 501, in send |
[2022-10-28 01:24:32,288] [util.py:162]               [DEBUG]    |     raise ConnectionError(err, request=request)                                                    |
[2022-10-28 01:24:32,288] [util.py:162]               [DEBUG]    | requests.exceptions.ConnectionError: ('Connection aborted.', ConnectionResetError(10054, 'An existing connection was forcibly closed by the remote host', None, 10054, None)) |
[2022-10-28 01:24:32,288] [util.py:162]               [DEBUG]    |                                                                                                    |
[2022-10-28 01:24:32,289] [plex_meta_manager.py:877]  [ERROR]    | Unknown Error: ('Connection aborted.', ConnectionResetError(10054, 'An existing connection was forcibly closed by the remote host', None, 10054, None)) |
[2022-10-28 01:24:32,289] [plex_meta_manager.py:880]  [INFO]     |                                                                                                    |
[2022-10-28 01:24:32,289] [util.py:209]               [INFO]     |====================================================================================================|
[2022-10-28 01:24:32,290] [util.py:216]               [INFO]     |                                      Finished A&E Collection                                       |
[2022-10-28 01:24:32,290] [util.py:216]               [INFO]     |                                    Collection Run Time: 0:00:00                                    |
[2022-10-28 01:24:32,290] [util.py:220]               [INFO]     |====================================================================================================|
